Workbook
Name UPDATE: 'Data Sheet'!$E$1

Sheet Teaser
B2: ='Data Sheet'!B1&" - One Page Profile" -> ITC LTD - One Page Profile
C3: Established in 1910, ITC is the largest cigarette manufacturer and seller in the country. ITC operates in four business segments at present — FMCG Cigarettes, FMCG Others, Paperboards, Paper and Packaging, and Agri Business.
B5: INR (Crs)
B6: Key Financial Metrics | D6: ='Data Sheet'!G16 -> 44286 | E6: ='Data Sheet'!H16 -> 44651 | F6: ='Data Sheet'!I16 -> 45016 | G6: ='Data Sheet'!J16 -> 45382 | H6: ='Data Sheet'!K16 -> 45747 | J6: Share Price - 5Y
B8: Total Sales | D8: ='Data Sheet'!G17 -> 49257.45 | E8: ='Data Sheet'!H17 -> 60644.54 | F8: ='Data Sheet'!I17 -> 70919.03 | G8: ='Data Sheet'!J17 -> 67931.94 | H8: ='Data Sheet'!K17 -> 75323.34
B9: Sales Growth (y-o-y) | D9: ='Data Sheet'!G34 -> -0.0026372963 | E9: ='Data Sheet'!H34 -> 0.23117498 | F9: ='Data Sheet'!I34 -> 0.16942152 | G9: ='Data Sheet'!J34 -> -0.042119724 | H9: ='Data Sheet'!K34 -> 0.10880596
B10: Gross Profit Margins (%) | D10: ='Data Sheet'!G37 -> 0.51867748 | E10: ='Data Sheet'!H37 -> 0.49650026 | F10: ='Data Sheet'!I37 -> 0.53068887 | G10: ='Data Sheet'!J37 -> 0.54582484 | H10: ='Data Sheet'!K37 -> 0.51209373
B11: EBITDA Margins (%) | D11: ='Profit & Loss'!G6/'Profit & Loss'!G4 -> 0.34644059 | E11: ='Profit & Loss'!H6/'Profit & Loss'!H4 -> 0.34006606 | F11: ='Profit & Loss'!I6/'Profit & Loss'!I4 -> 0.36244517 | G11: ='Profit & Loss'!J6/'Profit & Loss'!J4 -> 0.37077596 | H11: ='Profit & Loss'!K6/'Profit & Loss'!K4 -> 0.34304706
B12: EBIT Margins (%) | D12: ='Profit & Loss'!G27 -> 0.31303265 | E12: ='Profit & Loss'!H27 -> 0.31149944 | F12: ='Profit & Loss'!I27 -> 0.33693707 | G12: ='Profit & Loss'!J27 -> 0.34842932 | H12: ='Profit & Loss'!K27 -> 0.32119035
B13: Net Profit Margins (%) | D13: ='Profit & Loss'!G28 -> 0.26719187 | E13: ='Profit & Loss'!H28 -> 0.25134431 | F13: ='Profit & Loss'!I28 -> 0.27061368 | G13: ='Profit & Loss'!J28 -> 0.30116584 | H13: ='Profit & Loss'!K28 -> 0.46129964
B14: Earning Per Share (in ₹) | D14: ='Profit & Loss'!G13 -> 10.692505 | E14: ='Profit & Loss'!H13 -> 12.368976 | F14: ='Profit & Loss'!I13 -> 15.442276 | G14: ='Profit & Loss'!J13 -> 16.387082 | H14: ='Profit & Loss'!K13 -> 27.765984
B15: EPS Growth (y-o-y) | D15: ='Profit & Loss'!G29 -> -0.14130126 | E15: ='Profit & Loss'!H29 -> 0.15678939 | F15: ='Profit & Loss'!I29 -> 0.2484684 | G15: ='Profit & Loss'!J29 -> 0.0611831 | H15: ='Profit & Loss'!K29 -> 0.69438246
B16: Dividend Per Share (in ₹) | D16: ='Profit & Loss'!G30 -> 10.75 | E16: ='Profit & Loss'!H30 -> 11.500004 | F16: ='Profit & Loss'!I30 -> 15.5 | G16: ='Profit & Loss'!J30 -> 13.749998 | H16: ='Profit & Loss'!K30 -> 14.349997
B17: DPS Growth (y-o-y) | D17: ='Profit & Loss'!G31 -> 0.059113555 | E17: ='Profit & Loss'!H31 -> 0.069767819 | F17: ='Profit & Loss'!I31 -> 0.34782561 | G17: ='Profit & Loss'!J31 -> -0.11290335 | H17: ='Profit & Loss'!K31 -> 0.043636312
B19: Key Financial Ratios | D19: =D6 -> 44286 | E19: =E6 -> 44651 | F19: =F6 -> 45016 | G19: =G6 -> 45382 | H19: =H6 -> 45747 | J19: Volume (in millions) - 5Y
B21: Price to Earning | D21: ='Profit & Loss'!G14 -> 19.155475 | E21: ='Profit & Loss'!H14 -> 18.995914 | F21: ='Profit & Loss'!I14 -> 23.2796 | G21: ='Profit & Loss'!J14 -> 24.502837 | H21: ='Profit & Loss'!K14 -> 14.757266
B22: EV/EBITDA | D22: ='Profit & Loss'!G38 -> 14.516487 | E22: ='Profit & Loss'!H38 -> 13.826369 | F22: ='Profit & Loss'!I38 -> 17.203375 | G22: ='Profit & Loss'!J38 -> 19.628122 | H22: ='Profit & Loss'!K38 -> 19.70001
B23: EV/Sales | D23: ='Profit & Loss'!G39 -> 5.0291002 | E23: ='Profit & Loss'!H39 -> 4.7018788 | F23: ='Profit & Loss'!I39 -> 6.2352802 | G23: ='Profit & Loss'!J39 -> 7.2776357 | H23: ='Profit & Loss'!K39 -> 6.7580305
B24: P/B | D24: ='Profit & Loss'!G40 -> 4.1049142 | E24: ='Profit & Loss'!H40 -> 4.565538 | F24: ='Profit & Loss'!I40 -> 6.3943079 | G24: ='Profit & Loss'!J40 -> 6.6354022 | H24: ='Profit & Loss'!K40 -> 7.2688428
B25: Retrun on Equity (%) | D25: ='Balance Sheet'!G23 -> 0.21809064 | E25: ='Balance Sheet'!H23 -> 0.24405605 | F25: ='Balance Sheet'!I23 -> 0.27751555 | G25: ='Balance Sheet'!J23 -> 0.2745887 | H25: ='Balance Sheet'!K23 -> 0.49616743
B26: Return on Capital Employed (%) | D26: ='Balance Sheet'!G24 -> 0.28527066 | E26: ='Balance Sheet'!H24 -> 0.33733253 | F26: ='Balance Sheet'!I24 -> 0.39333609 | G26: ='Balance Sheet'!J24 -> 0.37429273 | H26: ='Balance Sheet'!K24 -> 0.57864605
B28: Top 10 Shareholders | C28: =Input!C24 -> N. share (in Crs.) | E28: =Input!D24 -> Shareholding (%) | G28: =Input!E24 -> Market Value (in Crs) | J28: Share Holding Pattern
B30: =Input!B25 -> Tobacco Manufacturers (India) Limited | D30: =Input!C25 -> 222.84959 | F30: =Input!D25 -> 0.1779 | H30: =Input!E25 -> 71089.018
B31: =Input!B26 -> Life Insurance Corporation of India | D31: =Input!C26 -> 196.57974 | F31: =Input!D26 -> 0.1569 | H31: =Input!E26 -> 62708.936
B32: =Input!B27 -> Specified Undertaking of the Unit Trust of India | D32: =Input!C27 -> 97.453143 | F32: =Input!D27 -> 0.0778 | H32: =Input!E27 -> 31087.553
B33: =Input!B28 -> Myddleton Investment Company Limited | D33: =Input!C28 -> 48.631194 | F33: =Input!D28 -> 0.0388 | H33: =Input!E28 -> 15513.351
B34: =Input!B29 -> SBI Mutual Funds | D34: =Input!C29 -> 41.195289 | F34: =Input!D29 -> 0.0329 | H34: =Input!E29 -> 13141.297
B35: =Input!B30 -> ICICI Prudential Mutual Funds | D35: =Input!C30 -> 38.82518 | F35: =Input!D30 -> 0.031 | H35: =Input!E30 -> 12385.232
B36: =Input!B31 -> QIB - Insurance Company Registered | D36: =Input!C31 -> 31.281378 | F36: =Input!D31 -> 0.025 | H36: =Input!E31 -> 9978.7597
B37: =Input!B32 -> GQG Partners Emerging Markets Equity Fund | D37: =Input!C32 -> 22.380053 | F37: =Input!D32 -> 0.0179 | H37: =Input!E32 -> 7139.2369
B38: =Input!B33 -> General Insurance Corporation of India | D38: =Input!C33 -> 21.708551 | F38: =Input!D33 -> 0.0173 | H38: =Input!E33 -> 6925.0277
B39: =Input!B34 -> NPS Trust (various Pension Funds) | D39: =Input!C34 -> 20.23053 | F39: =Input!D34 -> 0.0162 | H39: =Input!E34 -> 6453.5389
B41: Managerial Remuneration | C41: Designation | E41: Remuneration | G41: X of Median Salary | J41: Captial Structure
B43: S Puri | C43: CMD | E43: 25.66 | G43: 377 : 1 | J43: Share Price as on 25/2/26 | M43: ='Data Sheet'!B8 -> 325.4
B44: S Dutta | C44: Exec Director (ED) | E44: 8.53 | G44: 132 : 1 | J44: Number of Share o/s | M44: ='Data Sheet'!B6 -> 1252.9229
B45: H Malik | C45: ED & CFO | E45: 4.94 | G45: 99 : 1 | J45: Market Capitalization | M45: =M43*M44 -> 407701.12
B46: B Sumant | C46: ED | E46: 11.81 | G46: 174 : 1 | J46: Less: Cash & Equivalents | M46: ='Data Sheet'!K69*-1 -> -4012.36
B47: R K Singhi | C47: Exec VP & CS | E47: 3.11 | G47: 47 : 1 | J47: Add: Total Debt | M47: ='Data Sheet'!K59 -> 284.54
J48: Enterprise Value | M48: =SUM(M45:M47) -> 403973.3 | N48: non controlling interest
B50: Recent Updates
...

Sheet Input
B2: Share Holding Pattern
C3: No. of Months Qtr. Ending | D3: 3 Mar-24 | E3: 3 Jun-24 | F3: 3 Sep-24 | G3: 3 Dec-24 | H3: 3 Mar-25 | I3: 3 Jun-25 | J3: 3 Sep-25 | K3: 3 Dec-25
B4: Indian Promoters | C4: % | D4: 0.00 | E4: 0.00 | F4: 0.00 | G4: 0.00 | H4: 0.00 | I4: 0.00 | J4: 0.00 | K4: 0.00
B5: Foreign Promoters | C5: % | D5: 0.00 | E5: 0.00 | F5: 0.00 | G5: 0.00 | H5: 0.00 | I5: 0.00 | J5: 0.00 | K5: 0.00
B6: Total Promoters | C6: % | D6: 0.00 | E6: 0.00 | F6: 0.00 | G6: 0.00 | H6: 0.00 | I6: 0.00 | J6: 0.00 | K6: 0.00
B7: Mutual Funds | C7: % | D7: 11.56 | E7: 11.93 | F7: 12.76 | G7: 12.87 | H7: 12.87 | I7: 13.76 | J7: 14.30 | K7: 16.17
B8: Financial institution/Banks/Insurance | C8: % | D8: 28.04 | E8: 27.97 | F8: 27.76 | G8: 27.96 | H8: 28.06 | I8: 28.26 | J8: 28.26 | K8: 28.05
B9: Government | C9: % | D9: 0.04 | E9: 0.04 | F9: 0.04 | G9: 0.04 | H9: 0.04 | I9: 0.04 | J9: 0.04 | K9: 0.04
B10: FII | C10: % | D10: 40.95 | E10: 40.47 | F10: 40.53 | G10: 40.17 | H10: 39.87 | I10: 37.98 | J10: 37.39 | K10: 36.11
B11: Other | C11: % | D11: 4.17 | E11: 4.12 | F11: 4.08 | G11: 4.09 | H11: 4.25 | I11: 4.88 | J11: 4.85 | K11: 4.68
B12: Total Institutions | C12: % | D12: 84.76 | E12: 84.53 | F12: 85.17 | G12: 85.13 | H12: 85.09 | I12: 84.92 | J12: 84.84 | K12: 85.05
B13: Bodies Corporate | C13: % | D13: 0.94 | E13: 0.99 | F13: 0.93 | G13: 0.89 | H13: 0.88 | I13: 0.89 | J13: 0.90 | K13: 0.92
B14: Individuals | C14: % | D14: 13.08 | E14: 13.30 | F14: 12.43 | G14: 12.39 | H14: 12.43 | I14: 12.58 | J14: 12.64 | K14: 12.42
B15: NRIs/OCBs | C15: % | D15: 0.87 | E15: 0.88 | F15: 0.88 | G15: 0.89 | H15: 0.90 | I15: 0.92 | J15: 0.93 | K15: 0.93
B16: ADR/GDR | C16: % | D16: 0.00 | E16: 0.00 | F16: 0.00 | G16: 0.00 | H16: 0.00 | I16: 0.00 | J16: 0.00 | K16: 0.00
B17: Others | C17: % | D17: 0.36 | E17: 0.30 | F17: 0.60 | G17: 0.71 | H17: 0.70 | I17: 0.69 | J17: 0.70 | K17: 0.68
B18: Total Non-Institution | C18: % | D18: 15.25 | E18: 15.47 | F18: 14.84 | G18: 14.88 | H18: 14.91 | I18: 15.08 | J18: 15.17 | K18: 14.95
B19: Total Public | C19: % | D19: 100.00 | E19: 100.00 | F19: 100.00 | G19: 100.00 | H19: 100.00 | I19: 100.00 | J19: 100.00 | K19: 100.00
B20: Grand Total | C20: % | D20: 100.00 | E20: 100.00 | F20: 100.00 | G20: 100.00 | H20: 100.00 | I20: 100.00 | J20: 100.00 | K20: 100.00
B21: Pledged Promoter Holding | C21: % | D21: 0.00 | E21: 0.00 | F21: 0.00 | G21: 0.00 | H21: 0.00 | I21: 0.00 | J21: 0.00 | K21: 0.00
B23: Top Shareholders of ITC
B24: Shareholder's name | C24: N. share (in Crs.) | D24: Shareholding (%) | E24: Market Value (in Crs)
B25: Tobacco Manufacturers (India) Limited | C25: 222.84959 | D25: 0.1779 | E25: =319*C25 -> 71089.018
B26: Life Insurance Corporation of India | C26: 196.57974 | D26: 0.1569 | E26: =319*C26 -> 62708.936
B27: Specified Undertaking of the Unit Trust of India | C27: 97.453143 | D27: 0.0778 | E27: =319*C27 -> 31087.553
B28: Myddleton Investment Company Limited | C28: 48.631194 | D28: 0.0388 | E28: =319*C28 -> 15513.351
B29: SBI Mutual Funds | C29: 41.195289 | D29: 0.0329 | E29: =319*C29 -> 13141.297
B30: ICICI Prudential Mutual Funds | C30: 38.82518 | D30: 0.031 | E30: =319*C30 -> 12385.232
B31: QIB - Insurance Company Registered | C31: 31.281378 | D31: 0.025 | E31: =319*C31 -> 9978.7597
B32: GQG Partners Emerging Markets Equity Fund | C32: 22.380053 | D32: 0.0179 | E32: =319*C32 -> 7139.2369
B33: General Insurance Corporation of India | C33: 21.708551 | D33: 0.0173 | E33: =319*C33 -> 6925.0277
B34: NPS Trust (various Pension Funds) | C34: 20.23053 | D34: 0.0162 | E34: =319*C34 -> 6453.5389
C36: 45992
B37: FII | C37: 0.3611
B38: DII | C38: 0.489
B39: Public | C39: 0.1495

Sheet Profit & Loss
A1: ='Data Sheet'!B1 -> ITC LTD | H1: =UPDATE | M1: SCREENER.IN
A3: Narration | B3: ='Data Sheet'!B16 -> 42460 | C3: ='Data Sheet'!C16 -> 42825 | D3: ='Data Sheet'!D16 -> 43190 | E3: ='Data Sheet'!E16 -> 43555 | F3: ='Data Sheet'!F16 -> 43921 | G3: ='Data Sheet'!G16 -> 44286 | H3: ='Data Sheet'!H16 -> 44651 | I3: ='Data Sheet'!I16 -> 45016 | ... K3: ='Data Sheet'!K16 -> 45747 | L3: Trailing | M3: Best Case | N3: Worst Case
A4: Sales | B4: ='Data Sheet'!B17 -> 39192.1 | C4: ='Data Sheet'!C17 -> 42767.6 | D4: ='Data Sheet'!D17 -> 43448.94 | E4: ='Data Sheet'!E17 -> 48339.58 | F4: ='Data Sheet'!F17 -> 49387.7 | G4: ='Data Sheet'!G17 -> 49257.45 | H4: ='Data Sheet'!H17 -> 60644.54 | I4: ='Data Sheet'!I17 -> 70919.03 | ... K4: ='Data Sheet'!K17 -> 75323.34 | L4: =SUM(Quarters!H4:K4) -> 79808.72 | M4: =$K4+M23*K4 -> 83518.968 | N4: =$K4+N23*L4 -> 81303.23
A5: Expenses | B5: =SUM('Data Sheet'!B18,'Data Sheet'!B20:B24, -1*'Data Sheet'!B19) -> 24660.61 | C5: =SUM('Data Sheet'!C18,'Data Sheet'!C20:C24, -1*'Data Sheet'!C19) -> 27298.09 | D5: =SUM('Data Sheet'!D18,'Data Sheet'!D20:D24, -1*'Data Sheet'!D19) -> 26928.35 | E5: =SUM('Data Sheet'!E18,'Data Sheet'!E20:E24, -1*'Data Sheet'!E19) -> 29802.19 | F5: =SUM('Data Sheet'!F18,'Data Sheet'!F20:F24, -1*'Data Sheet'!F19) -> 30044.16 | G5: =SUM('Data Sheet'!G18,'Data Sheet'!G20:G24, -1*'Data Sheet'!G19) -> 32192.67 | H5: =SUM('Data Sheet'!H18,'Data Sheet'!H20:H24, -1*'Data Sheet'!H19) -> 40021.39 | I5: =SUM('Data Sheet'!I18,'Data Sheet'!I20:I24, -1*'Data Sheet'!I19) -> 45214.77 | ... K5: =SUM('Data Sheet'!K18,'Data Sheet'!K20:K24, -1*'Data Sheet'!K19) -> 49483.89 | L5: =SUM(Quarters!H5:K5) -> 52895.65 | M5: =M4-M6 -> 53597.014 | N5: =N4-N6 -> 53886.182
A6: Operating Profit | B6: =B4-B5 -> 14531.49 | C6: =C4-C5 -> 15469.51 | D6: =D4-D5 -> 16520.59 | E6: =E4-E5 -> 18537.39 | F6: =F4-F5 -> 19343.54 | G6: =G4-G5 -> 17064.78 | H6: =H4-H5 -> 20623.15 | I6: =I4-I5 -> 25704.26 | ... K6: =K4-K5 -> 25839.45 | L6: =SUM(Quarters!H6:K6) -> 26913.07 | M6: =M4*M24 -> 29921.955 | N6: =N4*N24 -> 27417.048
A7: Other Income | B7: ='Data Sheet'!B25 -> 1483.11 | C7: ='Data Sheet'!C25 -> 1758.63 | D7: ='Data Sheet'!D25 -> 2239.81 | E7: ='Data Sheet'!E25 -> 2080.44 | F7: ='Data Sheet'!F25 -> 2417.32 | G7: ='Data Sheet'!G25 -> 2576.95 | H7: ='Data Sheet'!H25 -> 1909.72 | I7: ='Data Sheet'!I25 -> 2097.64 | ... K7: ='Data Sheet'!K25 -> 17794.88 | L7: =SUM(Quarters!H7:K7) -> 17202.94 | M7: 0 | N7: 0
A8: Depreciation | B8: ='Data Sheet'!B26 -> 1077.4 | C8: ='Data Sheet'!C26 -> 1152.79 | D8: ='Data Sheet'!D26 -> 1236.28 | E8: ='Data Sheet'!E26 -> 1396.61 | F8: ='Data Sheet'!F26 -> 1644.91 | G8: ='Data Sheet'!G26 -> 1645.59 | H8: ='Data Sheet'!H26 -> 1732.41 | I8: ='Data Sheet'!I26 -> 1809.01 | ... K8: ='Data Sheet'!K26 -> 1646.32 | L8: =SUM(Quarters!H8:K8) -> 1699.61 | M8: =+$L8 -> 1699.61 | N8: =+$L8 -> 1699.61
A9: Interest | B9: ='Data Sheet'!B27 -> 78.13 | C9: ='Data Sheet'!C27 -> 49.03 | D9: ='Data Sheet'!D27 -> 115.01 | E9: ='Data Sheet'!E27 -> 71.4 | F9: ='Data Sheet'!F27 -> 81.38 | G9: ='Data Sheet'!G27 -> 57.97 | H9: ='Data Sheet'!H27 -> 59.99 | I9: ='Data Sheet'!I27 -> 77.77 | ... K9: ='Data Sheet'!K27 -> 45.06 | L9: =SUM(Quarters!H9:K9) -> 66.9 | M9: =+$L9 -> 66.9 | N9: =+$L9 -> 66.9
A10: Profit before tax | B10: ='Data Sheet'!B28 -> 14859.07 | C10: ='Data Sheet'!C28 -> 16026.32 | D10: ='Data Sheet'!D28 -> 17409.11 | E10: ='Data Sheet'!E28 -> 19149.82 | F10: ='Data Sheet'!F28 -> 20034.57 | G10: ='Data Sheet'!G28 -> 17938.17 | H10: ='Data Sheet'!H28 -> 20740.47 | I10: ='Data Sheet'!I28 -> 25915.12 | ... K10: ='Data Sheet'!K28 -> 41942.95 | L10: =SUM(Quarters!H10:K10) -> 42349.5 | M10: =M6+M7-SUM(M8:M9) -> 28155.445 | N10: =N6+N7-SUM(N8:N9) -> 25650.538
A11: Tax | B11: ='Data Sheet'!B29 -> 5358.21 | C11: ='Data Sheet'!C29 -> 5549.09 | D11: ='Data Sheet'!D29 -> 5916.43 | E11: ='Data Sheet'!E29 -> 6313.92 | F11: ='Data Sheet'!F29 -> 4441.79 | G11: ='Data Sheet'!G29 -> 4555.29 | H11: ='Data Sheet'!H29 -> 5237.34 | I11: ='Data Sheet'!I29 -> 6438.4 | ... K11: ='Data Sheet'!K29 -> 6890.47 | L11: =SUM(Quarters!H11:K11) -> 6993.21 | M11: =IF($L10>0,$L11/$L10,0) -> 0.16513088 | N11: =IF($L10>0,$L11/$L10,0) -> 0.16513088
A12: Net profit | B12: ='Data Sheet'!B30 -> 9344.45 | C12: ='Data Sheet'!C30 -> 10289.44 | D12: ='Data Sheet'!D30 -> 11271.2 | E12: ='Data Sheet'!E30 -> 12592.33 | F12: ='Data Sheet'!F30 -> 15306.23 | G12: ='Data Sheet'!G30 -> 13161.19 | H12: ='Data Sheet'!H30 -> 15242.66 | I12: ='Data Sheet'!I30 -> 19191.66 | ... K12: ='Data Sheet'!K30 -> 34746.63 | L12: =SUM(Quarters!H12:K12) -> 35028.87 | M12: =M10-M11*M10 -> 23506.111 | N12: =N10-N11*N10 -> 21414.842
A13: EPS | B13: =IF('Data Sheet'!B93>0,B12/'Data Sheet'!B93,0) -> 7.7413676 | C13: =IF('Data Sheet'!C93>0,C12/'Data Sheet'!C93,0) -> 8.4704875 | D13: =IF('Data Sheet'!D93>0,D12/'Data Sheet'!D93,0) -> 9.2354334 | E13: =IF('Data Sheet'!E93>0,E12/'Data Sheet'!E93,0) -> 10.272242 | F13: =IF('Data Sheet'!F93>0,F12/'Data Sheet'!F93,0) -> 12.451986 | G13: =IF('Data Sheet'!G93>0,G12/'Data Sheet'!G93,0) -> 10.692505 | H13: =IF('Data Sheet'!H93>0,H12/'Data Sheet'!H93,0) -> 12.368976 | I13: =IF('Data Sheet'!I93>0,I12/'Data Sheet'!I93,0) -> 15.442276 | ... K13: =IF('Data Sheet'!K93>0,K12/'Data Sheet'!K93,0) -> 27.765984 | L13: =IF('Data Sheet'!$B6>0,'Profit & Loss'!L12/'Data Sheet'!$B6,0) -> 27.957721 | M13: =IF('Data Sheet'!$B6>0,'Profit & Loss'!M12/'Data Sheet'!$B6,0) -> 18.76102 | N13: =IF('Data Sheet'!$B6>0,'Profit & Loss'!N12/'Data Sheet'!$B6,0) -> 17.091907
A14: Price to earning | B14: =IF(B15>0,B15/B13,"") -> 26.497902 | C14: =IF(C15>0,C15/C13,"") -> 31.019466 | D14: =IF(D15>0,D15/D13,"") -> 25.93273 | E14: =IF(E15>0,E15/E13,"") -> 27.12553 | F14: =IF(F15>0,F15/F13,"") -> 12.925649 | G14: =IF(G15>0,G15/G13,"") -> 19.155475 | H14: =IF(H15>0,H15/H13,"") -> 18.995914 | I14: =IF(I15>0,I15/I13,"") -> 23.2796 | ... K14: =IF(K15>0,K15/K13,"") -> 14.757266 | L14: =IF(L13>0,L15/L13,0) -> 11.639003 | M14: =M25 -> 18.544677 | N14: =N25 -> 11.639003
A15: Price | B15: ='Data Sheet'!B90 -> 205.13 | C15: ='Data Sheet'!C90 -> 262.75 | D15: ='Data Sheet'!D90 -> 239.5 | E15: ='Data Sheet'!E90 -> 278.64 | F15: ='Data Sheet'!F90 -> 160.95 | G15: ='Data Sheet'!G90 -> 204.82 | H15: ='Data Sheet'!H90 -> 234.96 | I15: ='Data Sheet'!I90 -> 359.49 | ... K15: ='Data Sheet'!K90 -> 409.75 | L15: ='Data Sheet'!B8 -> 325.4 | M15: =M13*M14 -> 347.91704 | N15: =N13*N14 -> 198.93276
A17: RATIOS:
A18: Dividend Payout | B18: =IF('Data Sheet'!B30>0, 'Data Sheet'!B31/'Data Sheet'!B30, 0) -> 0.73199814 | C18: =IF('Data Sheet'!C30>0, 'Data Sheet'!C31/'Data Sheet'!C30, 0) -> 0.56077104 | D18: =IF('Data Sheet'!D30>0, 'Data Sheet'!D31/'Data Sheet'!D30, 0) -> 0.5576345 | E18: =IF('Data Sheet'!E30>0, 'Data Sheet'!E31/'Data Sheet'!E30, 0) -> 0.55976138 | F18: =IF('Data Sheet'!F30>0, 'Data Sheet'!F31/'Data Sheet'!F30, 0) -> 0.81513083 | G18: =IF('Data Sheet'!G30>0, 'Data Sheet'!G31/'Data Sheet'!G30, 0) -> 1.0053772 | H18: =IF('Data Sheet'!H30>0, 'Data Sheet'!H31/'Data Sheet'!H30, 0) -> 0.92974586 | I18: =IF('Data Sheet'!I30>0, 'Data Sheet'!I31/'Data Sheet'!I30, 0) -> 1.0037381 | ... K18: =IF('Data Sheet'!K30>0, 'Data Sheet'!K31/'Data Sheet'!K30, 0) -> 0.51681933
A19: OPM | B19: =IF(B6>0,B6/B4,0) -> 0.370776 | C19: =IF(C6>0,C6/C4,0) -> 0.36171097 | D19: =IF(D6>0,D6/D4,0) -> 0.38022999 | E19: =IF(E6>0,E6/E4,0) -> 0.38348265 | F19: =IF(F6>0,F6/F4,0) -> 0.39166716 | G19: =IF(G6>0,G6/G4,0) -> 0.34644059 | H19: =IF(H6>0,H6/H4,0) -> 0.34006606 | I19: =IF(I6>0,I6/I4,0) -> 0.36244517 | ... L19: =IF(L6>0,L6/L4,0) -> 0.33721967
G22: TRENDS: | H22: 10 YEARS | I22: 7 YEARS | J22: 5 YEARS | K22: 3 YEARS | L22: RECENT | M22: BEST | N22: WORST
G23: Sales Growth | H23: =IF(B4=0,"",POWER($K4/B4,1/9)-1) -> 0.075290157 | I23: =IF(D4=0,"",POWER($K4/D4,1/7)-1) -> 0.081772082 | J23: =IF(F4=0,"",POWER($K4/F4,1/5)-1) -> 0.088083322 | K23: =IF(H4=0,"",POWER($K4/H4, 1/3)-1) -> 0.074927782 | L23: =IF(ISERROR(MAX(IF(J4=0,"",(K4-J4)/J4),IF(K4=0,"",(L4-K4)/K4))),"",MAX(IF(J4=0,"",(K4-J4)/J4),IF(K4=0,"",(L4-K4)/K4))) -> 0.10880596 | M23: =MAX(K23:L23) -> 0.10880596 | N23: =MIN(H23:L23) -> 0.074927782
G24: OPM | H24: =IF(SUM(B4:$K$4)=0,"",SUMPRODUCT(B19:$K$19,B4:$K$4)/SUM(B4:$K$4)) -> 0.36333562 | I24: =IF(SUM(E4:$K$4)=0,"",SUMPRODUCT(E19:$K$19,E4:$K$4)/SUM(E4:$K$4)) -> 0.36106877 | J24: =IF(SUM(G4:$K$4)=0,"",SUMPRODUCT(G19:$K$19,G4:$K$4)/SUM(G4:$K$4)) -> 0.35306244 | K24: =IF(SUM(I4:$K$4)=0, "", SUMPRODUCT(I19:$K$19,I4:$K$4)/SUM(I4:$K$4)) -> 0.35826538 | L24: =L19 -> 0.33721967 | M24: =MAX(K24:L24) -> 0.35826538 | N24: =MIN(H24:L24) -> 0.33721967
G25: Price to Earning | H25: =IF(ISERROR(AVERAGEIF(B14:$L14,">0")),"",AVERAGEIF(B14:$L14,">0")) -> 21.439216 | I25: =IF(ISERROR(AVERAGEIF(E14:$L14,">0")),"",AVERAGEIF(E14:$L14,">0")) -> 19.047659 | J25: =IF(ISERROR(AVERAGEIF(G14:$L14,">0")),"",AVERAGEIF(G14:$L14,">0")) -> 18.721682 | K25: =IF(ISERROR(AVERAGEIF(I14:$L14,">0")),"",AVERAGEIF(I14:$L14,">0")) -> 18.544677 | L25: =L14 -> 11.639003 | M25: =MAX(K25:L25) -> 18.544677 | N25: =MIN(H25:L25) -> 11.639003
A27: EBIT Margins | B27: =(B6-B8)/B4 -> 0.34328576 | C27: =(C6-C8)/C4 -> 0.33475622 | D27: =(D6-D8)/D4 -> 0.35177636 | E27: =(E6-E8)/E4 -> 0.354591 | F27: =(F6-F8)/F4 -> 0.35836109 | G27: =(G6-G8)/G4 -> 0.31303265 | H27: =(H6-H8)/H4 -> 0.31149944 | I27: =(I6-I8)/I4 -> 0.33693707 | ... K27: =(K6-K8)/K4 -> 0.32119035
A28: Net Margins | B28: =B12/B4 -> 0.23842688 | C28: =C12/C4 -> 0.24058961 | D28: =D12/D4 -> 0.25941254 | E28: =E12/E4 -> 0.2604973 | F28: =F12/F4 -> 0.30991988 | G28: =G12/G4 -> 0.26719187 | H28: =H12/H4 -> 0.25134431 | I28: =I12/I4 -> 0.27061368 | ... K28: =K12/K4 -> 0.46129964
A29: EPS Growth | C29: =C13/B13-1 -> 0.094184898 | D29: =D13/C13-1 -> 0.090307187 | E29: =E13/D13-1 -> 0.11226415 | F29: =F13/E13-1 -> 0.21219753 | G29: =G13/F13-1 -> -0.14130126 | H29: =H13/G13-1 -> 0.15678939 | I29: =I13/H13-1 -> 0.2484684 | J29: =J13/I13-1 -> 0.0611831 | K29: =K13/J13-1 -> 0.69438246
A30: Dividend per Share | B30: =B13*B18 -> 5.6666667 | C30: =C13*C18 -> 4.7500041 | D30: =D13*D18 -> 5.1499963 | E30: =E13*E18 -> 5.7500041 | F30: =F13*F18 -> 10.149998 | G30: =G13*G18 -> 10.75 | H30: =H13*H18 -> 11.500004 | I30: =I13*I18 -> 15.5 | ... K30: =K13*K18 -> 14.349997
A31: DPS Growth | C31: =C30/B30-1 -> -0.16176398 | D31: =D30/C30-1 -> 0.084208811 | E31: =E30/D30-1 -> 0.11650645 | F31: =F30/E30-1 -> 0.76521571 | G31: =G30/F30-1 -> 0.059113555 | H31: =H30/G30-1 -> 0.069767819 | I31: =I30/H30-1 -> 0.34782561 | J31: =J30/I30-1 -> -0.11290335 | K31: =K30/J30-1 -> 0.043636312
A33: Market Capitalization | B33: ='Data Sheet'!B93*'Data Sheet'!B90 -> 247608.32 | C33: ='Data Sheet'!C93*'Data Sheet'!C90 -> 319172.93 | D33: ='Data Sheet'!D93*'Data Sheet'!D90 -> 292292.99 | E33: ='Data Sheet'!E93*'Data Sheet'!E90 -> 341573.63 | F33: ='Data Sheet'!F93*'Data Sheet'!F90 -> 197842.96 | G33: ='Data Sheet'!G93*'Data Sheet'!G90 -> 252108.84 | H33: ='Data Sheet'!H93*'Data Sheet'!H90 -> 289548.26 | I33: ='Data Sheet'!I93*'Data Sheet'!I90 -> 446774.17 | ... K33: ='Data Sheet'!K93*'Data Sheet'!K90 -> 512765.25
A34: Debt | B34: ='Data Sheet'!B59 -> 83.78 | C34: ='Data Sheet'!C59 -> 45.72 | D34: ='Data Sheet'!D59 -> 35.92 | E34: ='Data Sheet'!E59 -> 13.44 | F34: ='Data Sheet'!F59 -> 277.45 | G34: ='Data Sheet'!G59 -> 270.83 | H34: ='Data Sheet'!H59 -> 249.44 | I34: ='Data Sheet'!I59 -> 306.04 | ... K34: ='Data Sheet'!K59 -> 284.54
A35: Cash | B35: ='Data Sheet'!B69 -> 6063.3 | C35: ='Data Sheet'!C69 -> 2967.4 | D35: ='Data Sheet'!D69 -> 2899.6 | E35: ='Data Sheet'!E69 -> 4152.03 | F35: ='Data Sheet'!F69 -> 7277.34 | G35: ='Data Sheet'!G69 -> 4659.02 | H35: ='Data Sheet'!H69 -> 4654.42 | I35: ='Data Sheet'!I69 -> 4880.19 | ... K35: ='Data Sheet'!K69 -> 4012.36
A36: Enterprise value | B36: =B33+B34-B35 -> 241628.8 | C36: =C33+C34-C35 -> 316251.25 | D36: =D33+D34-D35 -> 289429.31 | E36: =E33+E34-E35 -> 337435.04 | F36: =F33+F34-F35 -> 190843.07 | G36: =G33+G34-G35 -> 247720.65 | H36: =H33+H34-H35 -> 285143.28 | I36: =I33+I34-I35 -> 442200.02 | ... K36: =K33+K34-K35 -> 509037.43
A38: EV/EBITDA | B38: =B36/'Profit & Loss'!B6 -> 16.627944 | C38: =C36/'Profit & Loss'!C6 -> 20.443521 | D38: =D36/'Profit & Loss'!D6 -> 17.519308 | E38: =E36/'Profit & Loss'!E6 -> 18.202942 | F38: =F36/'Profit & Loss'!F6 -> 9.8659847 | G38: =G36/'Profit & Loss'!G6 -> 14.516487 | H38: =H36/'Profit & Loss'!H6 -> 13.826369 | I38: =I36/'Profit & Loss'!I6 -> 17.203375 | ... K38: =K36/'Profit & Loss'!K6 -> 19.70001
A39: EV/Sale | B39: =B36/B4 -> 6.1652425 | C39: =C36/C4 -> 7.3946458 | D39: =D36/D4 -> 6.6613663 | E39: =E36/E4 -> 6.9805125 | F39: =F36/F4 -> 3.8641822 | G39: =G36/G4 -> 5.0291002 | H39: =H36/H4 -> 4.7018788 | I39: =I36/I4 -> 6.2352802 | ... K39: =K36/K4 -> 6.7580305
A40: P/B | B40: =B36/'Data Sheet'!B35 -> 5.6614695 | C40: =C36/'Data Sheet'!C35 -> 6.813861 | D40: =D36/'Data Sheet'!D35 -> 5.5118777 | E40: =E36/'Data Sheet'!E35 -> 5.7056151 | F40: =F36/'Data Sheet'!F35 -> 2.9237557 | G40: =G36/'Data Sheet'!G35 -> 4.1049142 | H40: =H36/'Data Sheet'!H35 -> 4.565538 | I40: =I36/'Data Sheet'!I35 -> 6.3943079 | ... K40: =K36/'Data Sheet'!K35 -> 7.2688428

Sheet Quarters
A1: ='Profit & Loss'!A1 -> ITC LTD | E1: =UPDATE | J1: SCREENER.IN
A3: Narration | B3: ='Data Sheet'!B41 -> 45199 | C3: ='Data Sheet'!C41 -> 45291 | D3: ='Data Sheet'!D41 -> 45382 | E3: ='Data Sheet'!E41 -> 45473 | F3: ='Data Sheet'!F41 -> 45565 | G3: ='Data Sheet'!G41 -> 45657 | H3: ='Data Sheet'!H41 -> 45747 | I3: ='Data Sheet'!I41 -> 45838 | ... K3: ='Data Sheet'!K41 -> 46022
A4: Sales | B4: ='Data Sheet'!B42 -> 17774.47 | C4: ='Data Sheet'!C42 -> 17195.24 | D4: ='Data Sheet'!D42 -> 17037.8 | E4: ='Data Sheet'!E42 -> 17777.81 | F4: ='Data Sheet'!F42 -> 19990.36 | G4: ='Data Sheet'!G42 -> 18790.17 | H4: ='Data Sheet'!H42 -> 18765 | I4: ='Data Sheet'!I42 -> 21494.79 | ... K4: ='Data Sheet'!K42 -> 20047.3
A5: Expenses | B5: ='Data Sheet'!B43 -> 11320.23 | C5: ='Data Sheet'!C43 -> 10985.01 | D5: ='Data Sheet'!D43 -> 10735.73 | E5: ='Data Sheet'!E43 -> 11232.97 | F5: ='Data Sheet'!F43 -> 13438.28 | G5: ='Data Sheet'!G43 -> 12428.27 | H5: ='Data Sheet'!H43 -> 12245.61 | I5: ='Data Sheet'!I43 -> 14678.32 | ... K5: ='Data Sheet'!K43 -> 13164.78
A6: Operating Profit | B6: ='Data Sheet'!B50 -> 6454.24 | C6: ='Data Sheet'!C50 -> 6210.23 | D6: ='Data Sheet'!D50 -> 6302.07 | E6: ='Data Sheet'!E50 -> 6544.84 | F6: ='Data Sheet'!F50 -> 6552.08 | G6: ='Data Sheet'!G50 -> 6361.9 | H6: ='Data Sheet'!H50 -> 6519.39 | I6: ='Data Sheet'!I50 -> 6816.47 | ... K6: ='Data Sheet'!K50 -> 6882.52
A7: Other Income | B7: ='Data Sheet'!B44 -> 673.5 | C7: ='Data Sheet'!C44 -> 820.26 | D7: ='Data Sheet'!D44 -> 868 | E7: ='Data Sheet'!E44 -> 771.13 | F7: ='Data Sheet'!F44 -> 690.31 | G7: ='Data Sheet'!G44 -> 803.4 | H7: ='Data Sheet'!H44 -> 15391.28 | I7: ='Data Sheet'!I44 -> 750.97 | ... K7: ='Data Sheet'!K44 -> 321.85
A8: Depreciation | B8: ='Data Sheet'!B45 -> 453.04 | C8: ='Data Sheet'!C45 -> 384.04 | D8: ='Data Sheet'!D45 -> 385.09 | E8: ='Data Sheet'!E45 -> 403.13 | F8: ='Data Sheet'!F45 -> 416.18 | G8: ='Data Sheet'!G45 -> 415.98 | H8: ='Data Sheet'!H45 -> 411.03 | I8: ='Data Sheet'!I45 -> 422.96 | ... K8: ='Data Sheet'!K45 -> 430.82
A9: Interest | B9: ='Data Sheet'!B46 -> 9.87 | C9: ='Data Sheet'!C46 -> 11.94 | D9: ='Data Sheet'!D46 -> 10.72 | E9: ='Data Sheet'!E46 -> 9.6 | F9: ='Data Sheet'!F46 -> 14.73 | G9: ='Data Sheet'!G46 -> 9.82 | H9: ='Data Sheet'!H46 -> 10.91 | I9: ='Data Sheet'!I46 -> 16.47 | ... K9: ='Data Sheet'!K46 -> 19.47
A10: Profit before tax | B10: ='Data Sheet'!B47 -> 6664.83 | C10: ='Data Sheet'!C47 -> 6634.51 | D10: ='Data Sheet'!D47 -> 6774.26 | E10: ='Data Sheet'!E47 -> 6903.24 | F10: ='Data Sheet'!F47 -> 6811.48 | G10: ='Data Sheet'!G47 -> 6739.5 | H10: ='Data Sheet'!H47 -> 21488.73 | I10: ='Data Sheet'!I47 -> 7128.01 | ... K10: ='Data Sheet'!K47 -> 6754.08
A11: Tax | B11: ='Data Sheet'!B48 -> 1700.31 | C11: ='Data Sheet'!C48 -> 1227.99 | D11: ='Data Sheet'!D48 -> 1583.55 | E11: ='Data Sheet'!E48 -> 1726.25 | F11: ='Data Sheet'!F48 -> 1757.05 | G11: ='Data Sheet'!G48 -> 1726.32 | H11: ='Data Sheet'!H48 -> 1680.85 | I11: ='Data Sheet'!I48 -> 1784.6 | ... K11: ='Data Sheet'!K48 -> 1735.63
A12: Net profit | B12: ='Data Sheet'!B49 -> 4898.07 | C12: ='Data Sheet'!C49 -> 5335.23 | D12: ='Data Sheet'!D49 -> 5120.55 | E12: ='Data Sheet'!E49 -> 5091.59 | F12: ='Data Sheet'!F49 -> 4992.87 | G12: ='Data Sheet'!G49 -> 4934.8 | H12: ='Data Sheet'!H49 -> 19727.37 | I12: ='Data Sheet'!I49 -> 5244.2 | ... K12: ='Data Sheet'!K49 -> 4931.19
A14: OPM | B14: =IF(B4>0,B6/B4,"") -> 0.36311856 | C14: =IF(C4>0,C6/C4,"") -> 0.36115983 | D14: =IF(D4>0,D6/D4,"") -> 0.36988754 | E14: =IF(E4>0,E6/E4,"") -> 0.36814658 | F14: =IF(F4>0,F6/F4,"") -> 0.32776198 | G14: =IF(G4>0,G6/G4,"") -> 0.33857597 | H14: =IF(H4>0,H6/H4,"") -> 0.34742286 | I14: =IF(I4>0,I6/I4,"") -> 0.31712196 | ... K14: =IF(K4>0,K6/K4,"") -> 0.34331406

Sheet Balance Sheet
A1: ='Profit & Loss'!A1 -> ITC LTD | E1: =UPDATE | J1: SCREENER.IN
A3: Narration | B3: ='Data Sheet'!B56 -> 42460 | C3: ='Data Sheet'!C56 -> 42825 | D3: ='Data Sheet'!D56 -> 43190 | E3: ='Data Sheet'!E56 -> 43555 | F3: ='Data Sheet'!F56 -> 43921 | G3: ='Data Sheet'!G56 -> 44286 | H3: ='Data Sheet'!H56 -> 44651 | I3: ='Data Sheet'!I56 -> 45016 | ... K3: ='Data Sheet'!K56 -> 45747
A4: Equity Share Capital | B4: ='Data Sheet'!B57 -> 804.72 | C4: ='Data Sheet'!C57 -> 1214.74 | D4: ='Data Sheet'!D57 -> 1220.43 | E4: ='Data Sheet'!E57 -> 1225.86 | F4: ='Data Sheet'!F57 -> 1229.22 | G4: ='Data Sheet'!G57 -> 1230.88 | H4: ='Data Sheet'!H57 -> 1232.33 | I4: ='Data Sheet'!I57 -> 1242.8 | ... K4: ='Data Sheet'!K57 -> 1251.41
A5: Reserves | B5: ='Data Sheet'!B58 -> 41874.8 | C5: ='Data Sheet'!C58 -> 45198.19 | D5: ='Data Sheet'!D58 -> 51289.68 | E5: ='Data Sheet'!E58 -> 57915.01 | F5: ='Data Sheet'!F58 -> 64044.04 | G5: ='Data Sheet'!G58 -> 59116.46 | H5: ='Data Sheet'!H58 -> 61223.24 | I5: ='Data Sheet'!I58 -> 67912.46 | ... K5: ='Data Sheet'!K58 -> 68778.64
A6: Borrowings | B6: ='Data Sheet'!B59 -> 83.78 | C6: ='Data Sheet'!C59 -> 45.72 | D6: ='Data Sheet'!D59 -> 35.92 | E6: ='Data Sheet'!E59 -> 13.44 | F6: ='Data Sheet'!F59 -> 277.45 | G6: ='Data Sheet'!G59 -> 270.83 | H6: ='Data Sheet'!H59 -> 249.44 | I6: ='Data Sheet'!I59 -> 306.04 | ... K6: ='Data Sheet'!K59 -> 284.54
A7: Other Liabilities | B7: ='Data Sheet'!B60 -> 8888.04 | C7: ='Data Sheet'!C60 -> 9439.67 | D7: ='Data Sheet'!D60 -> 11694.85 | E7: ='Data Sheet'!E60 -> 12584.73 | F7: ='Data Sheet'!F60 -> 11760.04 | G7: ='Data Sheet'!G60 -> 13142.59 | H7: ='Data Sheet'!H60 -> 14491.01 | I7: ='Data Sheet'!I60 -> 16369.66 | ... K7: ='Data Sheet'!K60 -> 17688.11
A8: Total | B8: ='Data Sheet'!B61 -> 51651.34 | C8: ='Data Sheet'!C61 -> 55898.32 | D8: ='Data Sheet'!D61 -> 64240.88 | E8: ='Data Sheet'!E61 -> 71739.04 | F8: ='Data Sheet'!F61 -> 77310.75 | G8: ='Data Sheet'!G61 -> 73760.76 | H8: ='Data Sheet'!H61 -> 77196.02 | I8: ='Data Sheet'!I61 -> 85830.96 | ... K8: ='Data Sheet'!K61 -> 88002.7
A10: Net Block | B10: ='Data Sheet'!B62 -> 15106.63 | C10: ='Data Sheet'!C62 -> 15893.48 | D10: ='Data Sheet'!D62 -> 16523.96 | E10: ='Data Sheet'!E62 -> 19374.19 | F10: ='Data Sheet'!F62 -> 21713.34 | G10: ='Data Sheet'!G62 -> 23298.48 | H10: ='Data Sheet'!H62 -> 24231.59 | I10: ='Data Sheet'!I62 -> 25851.27 | ... K10: ='Data Sheet'!K62 -> 21954.85
A11: Capital Work in Progress | B11: ='Data Sheet'!B63 -> 2559.72 | C11: ='Data Sheet'!C63 -> 3729.89 | D11: ='Data Sheet'!D63 -> 5508.33 | E11: ='Data Sheet'!E63 -> 4136.42 | F11: ='Data Sheet'!F63 -> 3256.46 | G11: ='Data Sheet'!G63 -> 4011.29 | H11: ='Data Sheet'!H63 -> 3225.54 | I11: ='Data Sheet'!I63 -> 3003.3 | ... K11: ='Data Sheet'!K63 -> 1090.91
A12: Investments | B12: ='Data Sheet'!B64 -> 11747.59 | C12: ='Data Sheet'!C64 -> 17581.38 | D12: ='Data Sheet'!D64 -> 22052.86 | E12: ='Data Sheet'!E64 -> 25043.49 | F12: ='Data Sheet'!F64 -> 28663.35 | G12: ='Data Sheet'!G64 -> 24870.87 | H12: ='Data Sheet'!H64 -> 24841.01 | I12: ='Data Sheet'!I64 -> 29415.02 | ... K12: ='Data Sheet'!K64 -> 34719.82
A13: Other Assets | B13: ='Data Sheet'!B65 -> 22237.4 | C13: ='Data Sheet'!C65 -> 18693.57 | D13: ='Data Sheet'!D65 -> 20155.73 | E13: ='Data Sheet'!E65 -> 23184.94 | F13: ='Data Sheet'!F65 -> 23677.6 | G13: ='Data Sheet'!G65 -> 21580.12 | H13: ='Data Sheet'!H65 -> 24897.88 | I13: ='Data Sheet'!I65 -> 27561.37 | ... K13: ='Data Sheet'!K65 -> 30237.12
A14: Total | B14: ='Data Sheet'!B66 -> 51651.34 | C14: ='Data Sheet'!C66 -> 55898.32 | D14: ='Data Sheet'!D66 -> 64240.88 | E14: ='Data Sheet'!E66 -> 71739.04 | F14: ='Data Sheet'!F66 -> 77310.75 | G14: ='Data Sheet'!G66 -> 73760.76 | H14: ='Data Sheet'!H66 -> 77196.02 | I14: ='Data Sheet'!I66 -> 85830.96 | ... K14: ='Data Sheet'!K66 -> 88002.7
A16: Working Capital | B16: =B13-B7 -> 13349.36 | C16: =C13-C7 -> 9253.9 | D16: =D13-D7 -> 8460.88 | E16: =E13-E7 -> 10600.21 | F16: =F13-F7 -> 11917.56 | G16: =G13-G7 -> 8437.53 | H16: =H13-H7 -> 10406.87 | I16: =I13-I7 -> 11191.71 | ... K16: =K13-K7 -> 12549.01
A17: Debtors | B17: ='Data Sheet'!B67 -> 1917.18 | C17: ='Data Sheet'!C67 -> 2474.29 | D17: ='Data Sheet'!D67 -> 2682.29 | E17: ='Data Sheet'!E67 -> 4035.28 | F17: ='Data Sheet'!F67 -> 2562.48 | G17: ='Data Sheet'!G67 -> 2501.7 | H17: ='Data Sheet'!H67 -> 2461.9 | I17: ='Data Sheet'!I67 -> 2956.17 | ... K17: ='Data Sheet'!K67 -> 4719.67
A18: Inventory | B18: ='Data Sheet'!B68 -> 9062.1 | C18: ='Data Sheet'!C68 -> 8116.1 | D18: ='Data Sheet'!D68 -> 7495.09 | E18: ='Data Sheet'!E68 -> 7859.56 | F18: ='Data Sheet'!F68 -> 8879.33 | G18: ='Data Sheet'!G68 -> 10397.16 | H18: ='Data Sheet'!H68 -> 10864.15 | I18: ='Data Sheet'!I68 -> 11771.16 | ... K18: ='Data Sheet'!K68 -> 15637.56
A20: Debtor Days | B20: =IF('Profit & Loss'!B4>0,'Balance Sheet'!B17/('Profit & Loss'!B4/365),0) -> 17.854892 | C20: =IF('Profit & Loss'!C4>0,'Balance Sheet'!C17/('Profit & Loss'!C4/365),0) -> 21.116823 | D20: =IF('Profit & Loss'!D4>0,'Balance Sheet'!D17/('Profit & Loss'!D4/365),0) -> 22.53302 | E20: =IF('Profit & Loss'!E4>0,'Balance Sheet'!E17/('Profit & Loss'!E4/365),0) -> 30.469383 | F20: =IF('Profit & Loss'!F4>0,'Balance Sheet'!F17/('Profit & Loss'!F4/365),0) -> 18.938019 | G20: =IF('Profit & Loss'!G4>0,'Balance Sheet'!G17/('Profit & Loss'!G4/365),0) -> 18.537714 | H20: =IF('Profit & Loss'!H4>0,'Balance Sheet'!H17/('Profit & Loss'!H4/365),0) -> 14.817385 | I20: =IF('Profit & Loss'!I4>0,'Balance Sheet'!I17/('Profit & Loss'!I4/365),0) -> 15.214563 | ... K20: =IF('Profit & Loss'!K4>0,'Balance Sheet'!K17/('Profit & Loss'!K4/365),0) -> 22.870462
A21: Inventory Turnover | B21: =IF('Balance Sheet'!B18>0,'Profit & Loss'!B4/'Balance Sheet'!B18,0) -> 4.3248364 | C21: =IF('Balance Sheet'!C18>0,'Profit & Loss'!C4/'Balance Sheet'!C18,0) -> 5.2694767 | D21: =IF('Balance Sheet'!D18>0,'Profit & Loss'!D4/'Balance Sheet'!D18,0) -> 5.7969871 | E21: =IF('Balance Sheet'!E18>0,'Profit & Loss'!E4/'Balance Sheet'!E18,0) -> 6.1504181 | F21: =IF('Balance Sheet'!F18>0,'Profit & Loss'!F4/'Balance Sheet'!F18,0) -> 5.5620976 | G21: =IF('Balance Sheet'!G18>0,'Profit & Loss'!G4/'Balance Sheet'!G18,0) -> 4.737587 | H21: =IF('Balance Sheet'!H18>0,'Profit & Loss'!H4/'Balance Sheet'!H18,0) -> 5.5820787 | I21: =IF('Balance Sheet'!I18>0,'Profit & Loss'!I4/'Balance Sheet'!I18,0) -> 6.0248123 | ... K21: =IF('Balance Sheet'!K18>0,'Profit & Loss'!K4/'Balance Sheet'!K18,0) -> 4.8168218
A23: Return on Equity | B23: =IF(SUM('Balance Sheet'!B4:B5)>0,'Profit & Loss'!B12/SUM('Balance Sheet'!B4:B5),"") -> 0.21894459 | C23: =IF(SUM('Balance Sheet'!C4:C5)>0,'Profit & Loss'!C12/SUM('Balance Sheet'!C4:C5),"") -> 0.22169339 | D23: =IF(SUM('Balance Sheet'!D4:D5)>0,'Profit & Loss'!D12/SUM('Balance Sheet'!D4:D5),"") -> 0.21464819 | E23: =IF(SUM('Balance Sheet'!E4:E5)>0,'Profit & Loss'!E12/SUM('Balance Sheet'!E4:E5),"") -> 0.21292095 | F23: =IF(SUM('Balance Sheet'!F4:F5)>0,'Profit & Loss'!F12/SUM('Balance Sheet'!F4:F5),"") -> 0.23449465 | G23: =IF(SUM('Balance Sheet'!G4:G5)>0,'Profit & Loss'!G12/SUM('Balance Sheet'!G4:G5),"") -> 0.21809064 | H23: =IF(SUM('Balance Sheet'!H4:H5)>0,'Profit & Loss'!H12/SUM('Balance Sheet'!H4:H5),"") -> 0.24405605 | I23: =IF(SUM('Balance Sheet'!I4:I5)>0,'Profit & Loss'!I12/SUM('Balance Sheet'!I4:I5),"") -> 0.27751555 | ... K23: =IF(SUM('Balance Sheet'!K4:K5)>0,'Profit & Loss'!K12/SUM('Balance Sheet'!K4:K5),"") -> 0.49616743
A24: Return on Capital Emp | C24: =IF((B4+B5+B6+C4+C5+C6)>0,('Profit & Loss'!C10+'Profit & Loss'!C9)*2/(B4+B5+B6+C4+C5+C6),"") -> 0.36034518 | D24: =IF((C4+C5+C6+D4+D5+D6)>0,('Profit & Loss'!D10+'Profit & Loss'!D9)*2/(C4+C5+C6+D4+D5+D6),"") -> 0.35400589 | E24: =IF((D4+D5+D6+E4+E5+E6)>0,('Profit & Loss'!E10+'Profit & Loss'!E9)*2/(D4+D5+D6+E4+E5+E6),"") -> 0.34415688 | F24: =IF((E4+E5+E6+F4+F5+F6)>0,('Profit & Loss'!F10+'Profit & Loss'!F9)*2/(E4+E5+E6+F4+F5+F6),"") -> 0.32261652 | G24: =IF((F4+F5+F6+G4+G5+G6)>0,('Profit & Loss'!G10+'Profit & Loss'!G9)*2/(F4+F5+F6+G4+G5+G6),"") -> 0.28527066 | H24: =IF((G4+G5+G6+H4+H5+H6)>0,('Profit & Loss'!H10+'Profit & Loss'!H9)*2/(G4+G5+G6+H4+H5+H6),"") -> 0.33733253 | I24: =IF((H4+H5+H6+I4+I5+I6)>0,('Profit & Loss'!I10+'Profit & Loss'!I9)*2/(H4+H5+H6+I4+I5+I6),"") -> 0.39333609 | J24: =IF((I4+I5+I6+J4+J5+J6)>0,('Profit & Loss'!J10+'Profit & Loss'!J9)*2/(I4+I5+I6+J4+J5+J6),"") -> 0.37429273 | K24: =IF((J4+J5+J6+K4+K5+K6)>0,('Profit & Loss'!K10+'Profit & Loss'!K9)*2/(J4+J5+J6+K4+K5+K6),"") -> 0.57864605

Sheet Cash Flow
A1: ='Balance Sheet'!A1 -> ITC LTD | E1: =UPDATE | J1: SCREENER.IN
A3: Narration | B3: ='Data Sheet'!B81 -> 42460 | C3: ='Data Sheet'!C81 -> 42825 | D3: ='Data Sheet'!D81 -> 43190 | E3: ='Data Sheet'!E81 -> 43555 | F3: ='Data Sheet'!F81 -> 43921 | G3: ='Data Sheet'!G81 -> 44286 | H3: ='Data Sheet'!H81 -> 44651 | I3: ='Data Sheet'!I81 -> 45016 | ... K3: ='Data Sheet'!K81 -> 45747
A4: Cash from Operating Activity | B4: ='Data Sheet'!B82 -> 9799.04 | C4: ='Data Sheet'!C82 -> 10627.31 | D4: ='Data Sheet'!D82 -> 13169.4 | E4: ='Data Sheet'!E82 -> 12583.41 | F4: ='Data Sheet'!F82 -> 14689.66 | G4: ='Data Sheet'!G82 -> 12526.97 | H4: ='Data Sheet'!H82 -> 15775.51 | I4: ='Data Sheet'!I82 -> 18877.55 | ... K4: ='Data Sheet'!K82 -> 17627.04
A5: Cash from Investing Activity | B5: ='Data Sheet'!B83 -> -3920.73 | C5: ='Data Sheet'!C83 -> -3250.93 | D5: ='Data Sheet'!D83 -> -7113.89 | E5: ='Data Sheet'!E83 -> -5545.68 | F5: ='Data Sheet'!F83 -> -6174.02 | G5: ='Data Sheet'!G83 -> 5739.98 | H5: ='Data Sheet'!H83 -> -2238.49 | I5: ='Data Sheet'!I83 -> -5732.29 | ... K5: ='Data Sheet'!K83 -> -563.84
A6: Cash from Financing Activity | B6: ='Data Sheet'!B84 -> -5612.52 | C6: ='Data Sheet'!C84 -> -7301.03 | D6: ='Data Sheet'!D84 -> -6221.13 | E6: ='Data Sheet'!E84 -> -6868.64 | F6: ='Data Sheet'!F84 -> -8181.48 | G6: ='Data Sheet'!G84 -> -18633.83 | H6: ='Data Sheet'!H84 -> -13580.5 | I6: ='Data Sheet'!I84 -> -13006.03 | ... K6: ='Data Sheet'!K84 -> -17037.4
A7: Net Cash Flow | B7: ='Data Sheet'!B85 -> 265.79 | C7: ='Data Sheet'!C85 -> 75.35 | D7: ='Data Sheet'!D85 -> -165.62 | E7: ='Data Sheet'!E85 -> 169.09 | F7: ='Data Sheet'!F85 -> 334.16 | G7: ='Data Sheet'!G85 -> -366.88 | H7: ='Data Sheet'!H85 -> -43.48 | I7: ='Data Sheet'!I85 -> 139.23 | ... K7: ='Data Sheet'!K85 -> 25.8

Sheet Customization
A1: How to use it?
A3: You can customize this workbook as you want.
B4: You can add custom formating, add conditional formating, add your own formulas… do ANYTHING.
B5: Please don't edit the "Data Sheet" only.
A7: After customization, you can upload this back on Screener.
B8: Upload on: | C8: https://www.screener.in/excel/
A10: Download your customized workbooks now onwards.
B11: Now whenever you will "Export to excel" from Screener, it will export your customized file.
A14: TESTING:
B15: This is a testing feature currently.
B16: You can report any formula errors on the worksheet at: support@screener.in

Sheet Data Sheet
A1: COMPANY NAME | B1: ITC LTD | E1: =IF(B2<>B3, "A NEW VERSION OF THE WORKSHEET IS AVAILABLE", "")
A2: LATEST VERSION | B2: 2.1 | E2: PLEASE DO NOT MAKE ANY CHANGES TO THIS SHEET
A3: CURRENT VERSION | B3: 2.1
A5: META
A6: Number of shares | B6: =IF(B9>0, B9/B8, 0) -> 1252.9229
A7: Face Value | B7: 1
A8: Current Price | B8: 325.4
A9: Market Capitalization | B9: 407701.12
A15: PROFIT & LOSS
A16: Report Date | B16: 42460 | C16: 42825 | D16: 43190 | E16: 43555 | F16: 43921 | G16: 44286 | H16: 44651 | I16: 45016 | J16: 45382 | K16: 45747
A17: Sales | B17: 39192.1 | C17: 42767.6 | D17: 43448.94 | E17: 48339.58 | F17: 49387.7 | G17: 49257.45 | H17: 60644.54 | I17: 70919.03 | J17: 67931.94 | K17: 75323.34
A18: Raw Material Cost | B18: 13763.88 | C18: 15456.59 | D18: 14827.72 | E18: 17623.52 | F18: 18048.6 | G18: 20776.71 | H18: 27071.07 | I18: 29364.36 | J18: 27348.57 | K18: 32704.37
A19: Change in Inventory | B19: 195.38 | C19: -592.57 | D19: -1027.76 | E19: 203.19 | F19: 703.13 | G19: 645.27 | H19: 686 | I19: 358.59 | J19: 367.77 | K19: 725.65
A20: Power and Fuel | B20: 571.88 | C20: 584.33 | D20: 653.5 | E20: 746.73 | F20: 780.85 | G20: 699.56 | H20: 889.77 | I20: 1232.34 | J20: 952.9 | K20: 975.35
A21: Other Mfr. Exp | B21: 1581.59 | C21: 1683.9 | D21: 1697.62 | E21: 1871.01 | F21: 1908.29 | G21: 1587.18 | H21: 1887.67 | I21: 2327.8 | J21: 2183.76 | K21: 2345.36
A22: Employee Cost | B22: 3440.97 | C22: 3631.73 | D22: 3760.9 | E22: 4177.88 | F22: 4295.79 | G22: 4463.33 | H22: 4890.55 | I22: 5736.22 | J22: 5548.53 | K22: 6169.78
A23: Selling and admin | B23: 4261.78 | C23: 4179.74 | D23: 3954.87 | E23: 4546.39 | F23: 4488.63 | G23: 4236.77 | H23: 4858.38 | I23: 5604.08 | J23: 5312.45 | K23: 5793.29
A24: Other Expenses | B24: 1235.89 | C24: 1169.23 | D24: 1005.98 | E24: 1039.85 | F24: 1225.13 | G24: 1074.39 | H24: 1109.95 | I24: 1308.56 | J24: 1765.97 | K24: 2221.39
A25: Other Income | B25: 1483.11 | C25: 1758.63 | D25: 2239.81 | E25: 2080.44 | F25: 2417.32 | G25: 2576.95 | H25: 1909.72 | I25: 2097.64 | J25: 3330.45 | K25: 17794.88
A26: Depreciation | B26: 1077.4 | C26: 1152.79 | D26: 1236.28 | E26: 1396.61 | F26: 1644.91 | G26: 1645.59 | H26: 1732.41 | I26: 1809.01 | J26: 1518.05 | K26: 1646.32
A27: Interest | B27: 78.13 | C27: 49.03 | D27: 115.01 | E27: 71.4 | F27: 81.38 | G27: 57.97 | H27: 59.99 | I27: 77.77 | J27: 39.11 | K27: 45.06
... A31: Dividend Amount | B31: 6840.12 | C31: 5770.02 | D31: 6285.21 | E31: 7048.7 | F31: 12476.58 | G31: 13231.96 | H31: 14171.8 | I31: 19263.4 | J31: 17166.46 | K31: 17957.73
A34: Sales Growth Y-o-Y | C34: =C17/B17-1 -> 0.09123012 | D34: =D17/C17-1 -> 0.015931219 | E34: =E17/D17-1 -> 0.11256063 | F34: =F17/E17-1 -> 0.021682439 | G34: =G17/F17-1 -> -0.0026372963 | H34: =H17/G17-1 -> 0.23117498 | I34: =I17/H17-1 -> 0.16942152 | J34: =J17/I17-1 -> -0.042119724 | K34: =K17/J17-1 -> 0.10880596
A35: Book Value | B35: =B57+B58 -> 42679.52 | C35: =C57+C58 -> 46412.93 | D35: =D57+D58 -> 52510.11 | E35: =E57+E58 -> 59140.87 | F35: =F57+F58 -> 65273.26 | G35: =G57+G58 -> 60347.34 | H35: =H57+H58 -> 62455.57 | I35: =I57+I58 -> 69155.26 | ... K35: =K57+K58 -> 70030.05
A36: Gross Profit | B36: =B17-B18-B19-B20-B21 -> 23079.37 | C36: =C17-C18-C19-C20-C21 -> 25635.35 | D36: =D17-D18-D19-D20-D21 -> 27297.86 | E36: =E17-E18-E19-E20-E21 -> 27895.13 | F36: =F17-F18-F19-F20-F21 -> 27946.83 | G36: =G17-G18-G19-G20-G21 -> 25548.73 | H36: =H17-H18-H19-H20-H21 -> 30110.03 | I36: =I17-I18-I19-I20-I21 -> 37635.94 | ... K36: =K17-K18-K19-K20-K21 -> 38572.61
A37: Gross Profit Margin | B37: =B36/B17 -> 0.58887812 | C37: =C36/C17 -> 0.59941054 | D37: =D36/D17 -> 0.62827448 | E37: =E36/E17 -> 0.57706604 | F37: =F36/F17 -> 0.5658662 | G37: =G36/G17 -> 0.51867748 | H37: =H36/H17 -> 0.49650026 | I37: =I36/I17 -> 0.53068887 | ... K37: =K36/K17 -> 0.51209373
A40: Quarters
A41: Report Date | B41: 45199 | C41: 45291 | D41: 45382 | E41: 45473 | F41: 45565 | G41: 45657 | H41: 45747 | I41: 45838 | J41: 45930 | K41: 46022
A42: Sales | B42: 17774.47 | C42: 17195.24 | D42: 17037.8 | E42: 17777.81 | F42: 19990.36 | G42: 18790.17 | H42: 18765 | I42: 21494.79 | J42: 19501.63 | K42: 20047.3
A43: Expenses | B43: 11320.23 | C43: 10985.01 | D43: 10735.73 | E43: 11232.97 | F43: 13438.28 | G43: 12428.27 | H43: 12245.61 | I43: 14678.32 | J43: 12806.94 | K43: 13164.78
A44: Other Income | B44: 673.5 | C44: 820.26 | D44: 868 | E44: 771.13 | F44: 690.31 | G44: 803.4 | H44: 15391.28 | I44: 750.97 | J44: 738.84 | K44: 321.85
A45: Depreciation | B45: 453.04 | C45: 384.04 | D45: 385.09 | E45: 403.13 | F45: 416.18 | G45: 415.98 | H45: 411.03 | I45: 422.96 | J45: 434.8 | K45: 430.82
A46: Interest | B46: 9.87 | C46: 11.94 | D46: 10.72 | E46: 9.6 | F46: 14.73 | G46: 9.82 | H46: 10.91 | I46: 16.47 | J46: 20.05 | K46: 19.47
A47: Profit before tax | B47: 6664.83 | C47: 6634.51 | D47: 6774.26 | E47: 6903.24 | F47: 6811.48 | G47: 6739.5 | H47: 21488.73 | I47: 7128.01 | J47: 6978.68 | K47: 6754.08
A48: Tax | B48: 1700.31 | C48: 1227.99 | D48: 1583.55 | E48: 1726.25 | F48: 1757.05 | G48: 1726.32 | H48: 1680.85 | I48: 1784.6 | J48: 1792.13 | K48: 1735.63
A49: Net profit | B49: 4898.07 | C49: 5335.23 | D49: 5120.55 | E49: 5091.59 | F49: 4992.87 | G49: 4934.8 | H49: 19727.37 | I49: 5244.2 | J49: 5126.11 | K49: 4931.19
A50: Operating Profit | B50: 6454.24 | C50: 6210.23 | D50: 6302.07 | E50: 6544.84 | F50: 6552.08 | G50: 6361.9 | H50: 6519.39 | I50: 6816.47 | J50: 6694.69 | K50: 6882.52
A55: BALANCE SHEET
A56: Report Date | B56: 42460 | C56: 42825 | D56: 43190 | E56: 43555 | F56: 43921 | G56: 44286 | H56: 44651 | I56: 45016 | J56: 45382 | K56: 45747
A57: Equity Share Capital | B57: 804.72 | C57: 1214.74 | D57: 1220.43 | E57: 1225.86 | F57: 1229.22 | G57: 1230.88 | H57: 1232.33 | I57: 1242.8 | J57: 1248.47 | K57: 1251.41
...

Sheet Sheet2
A1: Date | B1: Adj Close | C1: Volume
A2: 44228 | B2: 215.95 | C2: 57744414
A3: 44229 | B3: 218.2 | C3: 48457781
A4: 44230 | B4: 216.75 | C4: 53643263
A5: 44231 | B5: 229.95 | C5: 105818897
A6: 44232 | B6: 234.35 | C6: 125490301
A7: 44235 | B7: 233.1 | C7: 41495834
A8: 44236 | B8: 229 | C8: 70655961
A9: 44237 | B9: 227.55 | C9: 47283127
A10: 44238 | B10: 226.45 | C10: 43631374
A11: 44239 | B11: 217.45 | C11: 110568108
A12: 44242 | B12: 218.6 | C12: 31776555
A13: 44243 | B13: 218.25 | C13: 29148891
... A1008: 45716 | B1008: 395 | C1008: 31954776
