Workbook

Sheet DCF>

Sheet WACC
B6: Weighted Average Cost of Capital
B8: All figures are in INR unless stated otherwise.
B10: Peer Comps
H11: Debt / | I11: Debt / | J11: Levered | K11: Unlevered
B12: Name of the Comp | D12: Country | E12: Total Debt | F12: Total Equity | G12: Tax Rate 1 | H12: Equity | I12: Capital | J12: Beta 2 | K12: Beta 3
B14: Indian Hotels Co | D14: India | E14: 3225.99 | F14: 95960.68 | G14: 0.3 | H14: =E14/F14 -> 0.033617832 | I14: =E14/(F14+E14) -> 0.032524431 | J14: ='Beta - Regression'!K9 -> -0.033561547 | K14: =J14/1+(1-G14)*H14 -> -0.010029064
B15: ITC Hotels | D15: India | E15: 80.23 | F15: 37650.19 | G15: 0.3 | H15: =E15/F15 -> 0.0021309321 | I15: =E15/(F15+E15) -> 0.0021264009 | J15: ='Beta - Regression'!K66 -> -0.22109799 | K15: =J15/1+(1-G15)*H15 -> -0.21960633
B16: EIH | D16: India | E16: 250.08 | F16: 19670.83 | G16: 0.3 | H16: =E16/F16 -> 0.012713241 | I16: =E16/(F16+E16) -> 0.012553643 | J16: ='Beta - Regression'!AB14 -> 0.21224947 | K16: =J16/1+(1-G16)*H16 -> 0.22114873
B17: Chalet Hotels | D17: India | E17: 2488.51 | F17: 19075.26 | G17: 0.3 | H17: =E17/F17 -> 0.13045746 | I17: =E17/(F17+E17) -> 0.11540236 | J17: ='Beta - Regression'!AB66 -> 0.26385767 | K17: =J17/1+(1-G17)*H17 -> 0.35517789
F19: Average | G19: =AVERAGE(G14:G17) -> 0.3 | H19: =AVERAGE(H14:H17) -> 0.044729867 | I19: =AVERAGE(I14:I17) -> 0.040651709 | J19: =AVERAGE(J14:J17) -> 0.055361901 | K19: =AVERAGE(K14:K17) -> 0.086672807
F20: Median | G20: =MEDIAN(G14:G17) -> 0.3 | H20: =MEDIAN(H14:H17) -> 0.023165536 | I20: =MEDIAN(I14:I17) -> 0.022539037 | J20: =MEDIAN(J14:J17) -> 0.089343959 | K20: =MEDIAN(K14:K17) -> 0.10555983
B23: Cost of Debt | G23: Cost of Equity
B25: Pre - Tax Cost of Debt | C25: Interest/debt | E25: =56/E14 -> 0.017359012 | G25: Risk Free Rate | K25: 0.067
B26: Tax Rate | E26: 0.3 | G26: Equity Risk Premium | K26: =Rm!F11-WACC!K25 -> 0.098392308
B27: Post Tax Cost of Debt | E27: =E25*(1-E26) -> 0.012151309 | G27: Levered Beta 4 | K27: =K36 -> 0.13588588
G28: Cost of Equity | K28: =K25+(K26*K27) -> 0.080370125
B31: Capital Structure | G31: Levered Beta
D33: Current | E33: Target | G33: Comps Median Unlivered Beta | K33: =K20 -> 0.10555983
B34: Total Debt | C34: =E14 -> 3225.99 | D34: =C34/$C$36 -> 0.032524431 | E34: =I19 -> 0.040651709 | G34: Target Debt / Equity | K34: =E38 -> 0.042374297
B35: Market Capitalization | C35: =F14 -> 95960.68 | D35: =C35/$C$36 -> 0.96747557 | E35: =E36-E34 -> 0.95934829 | G35: Tax Rate | K35: =E26 -> 0.3
B36: Total Capital | C36: =SUM(C34:C35) -> 99186.67 | D36: =SUM(D34:D35) -> 1 | E36: =D36 -> 1 | G36: Levered Beta | K36: =K33*(1+(1-K34)*K35) -> 0.13588588
B38: Debt / Equity | D38: =D34/D35 -> 0.033617832 | E38: =E34/E35 -> 0.042374297 | G38: Weighted Average Cost of Capital
B40: Notes: | J40: Total Cost | K40: Total Weight
B41: 1. Tax Rate Considered as Marginal Tax Rate for the country | G41: Debt | J41: =E27 -> 0.012151309 | K41: =E34 -> 0.040651709
B42: 2. Levered beta is based on 5 year monthly data | G42: Equity | J42: =K28 -> 0.080370125 | K42: =E35 -> 0.95934829
B43: 3. Unlevered beta = Levered beta/(1+(1-Tax Rate)*Debt/Equity) | G43: Weighted Average Cost of Capital | K43: =SUMPRODUCT(J41:J42,K41:K42) -> 0.077596914
B44: 4. Unlevered beta = Levered beta*(1+(1-Tax Rate)*Debt/Equity)

Sheet Data>
A1: Da

Sheet Beta - Regression
B5: Regression Beta - 5 Years Monthly
S6: EIH Monthly Returns | X6: Nifty Returns | AA6: Beta Drifting
B7: The Indian Hotels Company Monthly Returns | G7: Nifty Returns | J7: Beta Drifting | M7: Beta 1 | N7: =SLOPE(H11:H55,D11:D55) -> -0.033561547 | O7: (Slope)
M8: Beta 2 | N8: =_xlfn.COVARIANCE.S(D11:D114,H10:H114)/_xlfn.VAR.S(H10:H114) -> #N/A | O8: (Covariance) | S8: Date | T8: Closing Price | U8: Return | X8: Closing Price | Y8: Return | AA8: Levered Raw Beta | AB8: =AE8 -> -0.050334046 | AD8: Beta 1 | AE8: =SLOPE(Y10:Y28,U10:U28) -> -0.050334046
B9: Date | C9: Closing Price | D9: Return | G9: Closing Price | H9: Return | J9: Levered Raw Beta | K9: =N7 -> -0.033561547 | S9: 46023 | T9: 332.25 | X9: 23054.4 | AA9: Raw Beta Weight | AB9: 0.75
B10: 46023 | C10: 690.15 | G10: 23054.4 | J10: Raw Beta Weight | K10: 0.75 | M10: Beta 3 | N10: =N29 -> 0 | S10: 45992 | T10: 358.65 | U10: =T10/T9-1 -> 0.079458239 | X10: 24013.9 | Y10: =X9/X10-1 -> -0.039956025
B11: 45992 | C11: 738.75 | D11: =C11/C10-1 -> 0.070419474 | G11: 24013.9 | H11: =G10/G11-1 -> -0.039956025 | S11: 45962 | T11: 364.85 | U11: =T11/T10-1 -> 0.017287049 | X11: 24131.1 | Y11: =X10/X11-1 -> -0.004856803 | AA11: Market Beta | AB11: 1
B12: 45962 | C12: 744.3 | D12: =C12/C11-1 -> 0.0075126904 | G12: 24131.1 | H12: =G11/G12-1 -> -0.004856803 | J12: Market Beta | K12: 1 | S12: 45931 | T12: 362.4 | U12: =T12/T11-1 -> -0.0067150884 | X12: 24205.35 | Y12: =X11/X12-1 -> -0.0030675037 | AA12: Market Beta Weight | AB12: 0.25
B13: 45931 | C13: 741.8 | D13: =C13/C12-1 -> -0.0033588607 | G13: 24205.35 | H13: =G12/G13-1 -> -0.0030675037 | J13: Market Beta Weight | K13: 0.25 | S13: 45901 | T13: 373.95 | U13: =T13/T12-1 -> 0.031870861 | X13: 25810.4 | Y13: =X12/X13-1 -> -0.062186173
B14: 45901 | C14: 720.3 | D14: =C14/C13-1 -> -0.028983554 | G14: 25810.4 | H14: =G13/G14-1 -> -0.062186173 | S14: 45870 | T14: 382.1 | U14: =T14/T13-1 -> 0.021794358 | X14: 25235.9 | Y14: =X13/X14-1 -> 0.022765188 | AA14: Adjusted Beta | AB14: =(AB8*AB9)+(AB11*AB12) -> 0.21224947
B15: 45870 | C15: 758.45 | D15: =C15/C14-1 -> 0.052964043 | G15: 25235.9 | H15: =G14/G15-1 -> 0.022765188 | J15: Adjusted Beta | K15: =(K9*K10)+(K12*K13) -> 0.22482884 | S15: 45839 | T15: 374.8 | U15: =T15/T14-1 -> -0.019104946 | X15: 24951.15 | Y15: =X14/X15-1 -> 0.0114123
B16: 45839 | C16: 740.75 | D16: =C16/C15-1 -> -0.023337069 | G16: 24951.15 | H16: =G15/G16-1 -> 0.0114123 | S16: 45809 | T16: 355.2 | U16: =T16/T15-1 -> -0.052294557 | X16: 24010.6 | Y16: =X15/X16-1 -> 0.039172282
B17: 45809 | C17: 760.3 | D17: =C17/C16-1 -> 0.02639217 | G17: 24010.6 | H17: =G16/G17-1 -> 0.039172282 | S17: 45778 | T17: 342.15 | U17: =T17/T16-1 -> -0.036739865 | X17: 22530.7 | Y17: =X16/X17-1 -> 0.065683712
B18: 45778 | C18: 769.85 | D18: =C18/C17-1 -> 0.012560831 | G18: 22530.7 | H18: =G17/G18-1 -> 0.065683712 | S18: 45748 | T18: 348.9 | U18: =T18/T17-1 -> 0.019728189 | X18: 22604.85 | Y18: =X17/X18-1 -> -0.0032802695
B19: 45748 | C19: 787.7 | D19: =C19/C18-1 -> 0.023186335 | G19: 22604.85 | H19: =G18/G19-1 -> -0.0032802695 | S19: 45717 | T19: 322.45 | U19: =T19/T18-1 -> -0.075809688 | X19: 22326.9 | Y19: =X18/X19-1 -> 0.012449108
B20: 45717 | C20: 787.55 | D20: =C20/C19-1 -> -0.00019042783 | G20: 22326.9 | H20: =G19/G20-1 -> 0.012449108 | S20: 45689 | T20: 315.6 | U20: =T20/T19-1 -> -0.021243604 | X20: 21982.8 | Y20: =X19/X20-1 -> 0.015653147
B21: 45689 | C21: 716.1 | D21: =C21/C20-1 -> -0.090724398 | G21: 21982.8 | H21: =G20/G21-1 -> 0.015653147 | S21: 45658 | T21: 324.7 | U21: =T21/T20-1 -> 0.028833967 | X21: 21697.45 | Y21: =X20/X21-1 -> 0.013151315
B22: 45658 | C22: 764.7 | D22: =C22/C21-1 -> 0.067867616 | G22: 21697.45 | H22: =G21/G22-1 -> 0.013151315 | S22: 45627 | T22: 358.25 | U22: =T22/T21-1 -> 0.10332615 | X22: 21731.4 | Y22: =X21/X22-1 -> -0.0015622555
B23: 45627 | C23: 877.55 | D23: =C23/C22-1 -> 0.14757421 | G23: 21731.4 | H23: =G22/G23-1 -> -0.0015622555 | S23: 45597 | T23: 342.1 | U23: =T23/T22-1 -> -0.045080251 | X23: 20133.15 | Y23: =X22/X23-1 -> 0.079384001
B24: 45597 | C24: 793.35 | D24: =C24/C23-1 -> -0.095948949 | G24: 20133.15 | H24: =G23/G24-1 -> 0.079384001 | S24: 45566 | T24: 315.3 | U24: =T24/T23-1 -> -0.078339667 | X24: 19079.6 | Y24: =X23/X24-1 -> 0.055218663
B25: 45566 | C25: 676.7 | D25: =C25/C24-1 -> -0.14703473 | G25: 19079.6 | H25: =G24/G25-1 -> 0.055218663 | S25: 45536 | T25: 335.45 | U25: =T25/T24-1 -> 0.06390739 | X25: 19638.3 | Y25: =X24/X25-1 -> -0.028449509
B26: 45536 | C26: 684.7 | D26: =C26/C25-1 -> 0.011822078 | G26: 19638.3 | H26: =G25/G26-1 -> -0.028449509 | S26: 45505 | T26: 352.1 | U26: =T26/T25-1 -> 0.049634819 | X26: 19253.8 | Y26: =X25/X26-1 -> 0.019970084
B27: 45505 | C27: 647.5 | D27: =C27/C26-1 -> -0.054330364 | G27: 19253.8 | H27: =G26/G27-1 -> 0.019970084 | S27: 45474 | T27: 740.1 | U27: =T27/T26-1 -> 1.1019597 | X27: 19753.8 | Y27: =X26/X27-1 -> -0.025311586
B28: 45474 | C28: 642.05 | D28: =C28/C27-1 -> -0.0084169884 | G28: 19753.8 | H28: =G27/G28-1 -> -0.025311586 | S28: 45444 | T28: 715.3 | U28: =T28/T27-1 -> -0.033508985 | X28: 19189.05 | Y28: =X27/X28-1 -> 0.029430847
B29: 45444 | C29: 625.05 | D29: =C29/C28-1 -> -0.026477689 | G29: 19189.05 | H29: =G28/G29-1 -> 0.029430847
B30: 45413 | C30: 557.4 | D30: =C30/C29-1 -> -0.10823134 | G30: 18534.4 | H30: =G29/G30-1 -> 0.035320809
B31: 45383 | C31: 576.75 | D31: =C31/C30-1 -> 0.034714747 | G31: 18065 | H31: =G30/G31-1 -> 0.025983947
B32: 45352 | C32: 591.15 | D32: =C32/C31-1 -> 0.02496749 | G32: 17359.75 | H32: =G31/G32-1 -> 0.040625585
B33: 45323 | C33: 586.7 | D33: =C33/C32-1 -> -0.0075277002 | G33: 17303.95 | H33: =G32/G33-1 -> 0.0032246973
B34: 45292 | C34: 492.65 | D34: =C34/C33-1 -> -0.16030339 | G34: 17662.15 | H34: =G33/G34-1 -> -0.020280657
B35: 45261 | C35: 438.35 | D35: =C35/C34-1 -> -0.11022024 | G35: 18105.3 | H35: =G34/G35-1 -> -0.024476258
B36: 45231 | C36: 421.7 | D36: =C36/C35-1 -> -0.037983347 | G36: 18758.35 | H36: =G35/G36-1 -> -0.03481383
B37: 45200 | C37: 383.4 | D37: =C37/C36-1 -> -0.09082286 | G37: 18012.2 | H37: =G36/G37-1 -> 0.041424701
B38: 45170 | C38: 411.1 | D38: =C38/C37-1 -> 0.072248305 | G38: 17094.35 | H38: =G37/G38-1 -> 0.053693179
B39: 45139 | C39: 420.9 | D39: =C39/C38-1 -> 0.023838482 | G39: 17759.3 | H39: =G38/G39-1 -> -0.037442354
B40: 45108 | C40: 395.1 | D40: =C40/C39-1 -> -0.06129722 | G40: 17158.25 | H40: =G39/G40-1 -> 0.035029796
... B55: 44652 | C55: 256.5 | D55: =C55/C54-1 -> 0.091489362 | G55: 14631.1 | H55: =G54/G55-1 -> 0.065046374
B58: ITC Hotels Monthly Returns | G58: Nifty Returns | J58: Beta Drifting | S58: Hotels Monthly Returns | X58: Nifty Returns | AA58: Beta Drifting
B60: Date | C60: Closing Price | D60: Return | G60: Closing Price | H60: Return | J60: Levered Raw Beta | K60: =N60 -> -0.62813065 | M60: Beta 1 | N60: =SLOPE(H62:H106,D62:D106) -> -0.62813065 | S60: Date | T60: Closing Price | U60: Return | X60: Closing Price | Y60: Return | AA60: Levered Raw Beta | AB60: =AE60 -> 0.018476894 | AD60: Beta 1 | AE60: =SLOPE(Y62:Y106,U62:U106) -> 0.018476894
B61: 46023 | C61: 158.45 | G61: 23054.4 | J61: Raw Beta Weight | K61: 0.75 | S61: 46023 | T61: 863.65 | X61: 23054.4 | AA61: Raw Beta Weight | AB61: 0.75
...

Sheet Rm
B6: Return on Markets
B8: Year | C8: Annual
B9: 2000 | C9: -0.1465 | E9: Average Return | F9: =AVERAGE(C9:C34) -> 0.15149231
B10: 2001 | C10: -0.1618 | E10: Dividend Yield | F10: 0.0139
B11: 2002 | C11: 0.0325 | E11: Total Market Return | F11: =SUM(F9:F10) -> 0.16539231
B12: 2003 | C12: 0.719
B13: 2004 | C13: 0.1068
B14: 2005 | C14: 0.3634
B15: 2006 | C15: 0.3983
B16: 2007 | C16: 0.5477
B17: 2008 | C17: -0.5179
B18: 2009 | C18: 0.7576
B19: 2010 | C19: 0.1795
B20: 2011 | C20: -0.2462
B21: 2012 | C21: 0.277
B22: 2013 | C22: 0.0676
B23: 2014 | C23: 0.3139
... B34: 2025 | C34: 0.1051
